WARNING:src.content_assistant_bot.database.core:One or more postgresql database environment variables are not set. Using SQLite instead.
INFO:apscheduler.scheduler:Scheduler started
INFO:src.content_assistant_bot.database.core:Tables dropped
INFO:src.content_assistant_bot.database.core:Tables created
INFO:src.content_assistant_bot.auth.service:User with name konverner added successfully.
INFO:__main__:Superuser konverner added successfully.
INFO:__main__:Database initialized
INFO:apscheduler.scheduler:Scheduler started
INFO:src.content_assistant_bot.scheduler.service:Scheduler started
INFO:__main__:Initializing telegram_bot v1.0.0
INFO:__main__:Enabling antiflood (window: 2s)
INFO:src.content_assistant_bot.admin.handlers:Registering `about` handlers
INFO:src.content_assistant_bot.channels.handlers:Registering channel handlers
INFO:src.content_assistant_bot.start.handlers:Registering menu handlers
INFO:src.content_assistant_bot.help.handlers:Registering menu handlers
INFO:src.content_assistant_bot.posts.handlers:Registering item handlers
INFO:src.content_assistant_bot.menu.handlers:Registering menu handlers
INFO:src.content_assistant_bot.public_message.handlers:Registering `public message` handlers
INFO:src.content_assistant_bot.users.handlers:Registering `about` handlers
INFO:src.content_assistant_bot.generation.handlers:Registering generation handlers
INFO:__main__:Bot sadflamebot (ID: 5131531473) initialized successfully
2025-03-21 16:40:56,219 (__init__.py:1241 MainThread) ERROR - TeleBot: "Threaded polling exception: A request to the Telegram API was unsuccessful. Error code: 409. Description: Conflict: terminated by other getUpdates request; make sure that only one bot instance is running"
ERROR:TeleBot:Threaded polling exception: A request to the Telegram API was unsuccessful. Error code: 409. Description: Conflict: terminated by other getUpdates request; make sure that only one bot instance is running
2025-03-21 16:40:56,221 (__init__.py:1243 MainThread) ERROR - TeleBot: "Exception traceback:
Traceback (most recent call last):
  File "/home/verner/content-assistant-bot/venv/lib/python3.10/site-packages/telebot/__init__.py", line 1234, in __threaded_polling
    polling_thread.raise_exceptions()
  File "/home/verner/content-assistant-bot/venv/lib/python3.10/site-packages/telebot/util.py", line 111, in raise_exceptions
    raise self.exception_info
  File "/home/verner/content-assistant-bot/venv/lib/python3.10/site-packages/telebot/util.py", line 93, in run
    task(*args, **kwargs)
  File "/home/verner/content-assistant-bot/venv/lib/python3.10/site-packages/telebot/__init__.py", line 688, in __retrieve_updates
    updates = self.get_updates(offset=(self.last_update_id + 1),
  File "/home/verner/content-assistant-bot/venv/lib/python3.10/site-packages/telebot/__init__.py", line 660, in get_updates
    json_updates = apihelper.get_updates(
  File "/home/verner/content-assistant-bot/venv/lib/python3.10/site-packages/telebot/apihelper.py", line 332, in get_updates
    return _make_request(token, method_url, params=payload)
  File "/home/verner/content-assistant-bot/venv/lib/python3.10/site-packages/telebot/apihelper.py", line 168, in _make_request
    json_result = _check_result(method_name, result)
  File "/home/verner/content-assistant-bot/venv/lib/python3.10/site-packages/telebot/apihelper.py", line 195, in _check_result
    raise ApiTelegramException(method_name, result, result_json)
telebot.apihelper.ApiTelegramException: A request to the Telegram API was unsuccessful. Error code: 409. Description: Conflict: terminated by other getUpdates request; make sure that only one bot instance is running
"
ERROR:TeleBot:Exception traceback:
Traceback (most recent call last):
  File "/home/verner/content-assistant-bot/venv/lib/python3.10/site-packages/telebot/__init__.py", line 1234, in __threaded_polling
    polling_thread.raise_exceptions()
  File "/home/verner/content-assistant-bot/venv/lib/python3.10/site-packages/telebot/util.py", line 111, in raise_exceptions
    raise self.exception_info
  File "/home/verner/content-assistant-bot/venv/lib/python3.10/site-packages/telebot/util.py", line 93, in run
    task(*args, **kwargs)
  File "/home/verner/content-assistant-bot/venv/lib/python3.10/site-packages/telebot/__init__.py", line 688, in __retrieve_updates
    updates = self.get_updates(offset=(self.last_update_id + 1),
  File "/home/verner/content-assistant-bot/venv/lib/python3.10/site-packages/telebot/__init__.py", line 660, in get_updates
    json_updates = apihelper.get_updates(
  File "/home/verner/content-assistant-bot/venv/lib/python3.10/site-packages/telebot/apihelper.py", line 332, in get_updates
    return _make_request(token, method_url, params=payload)
  File "/home/verner/content-assistant-bot/venv/lib/python3.10/site-packages/telebot/apihelper.py", line 168, in _make_request
    json_result = _check_result(method_name, result)
  File "/home/verner/content-assistant-bot/venv/lib/python3.10/site-packages/telebot/apihelper.py", line 195, in _check_result
    raise ApiTelegramException(method_name, result, result_json)
telebot.apihelper.ApiTelegramException: A request to the Telegram API was unsuccessful. Error code: 409. Description: Conflict: terminated by other getUpdates request; make sure that only one bot instance is running

2025-03-21 16:40:59,857 (__init__.py:1241 MainThread) ERROR - TeleBot: "Threaded polling exception: A request to the Telegram API was unsuccessful. Error code: 409. Description: Conflict: terminated by other getUpdates request; make sure that only one bot instance is running"
ERROR:TeleBot:Threaded polling exception: A request to the Telegram API was unsuccessful. Error code: 409. Description: Conflict: terminated by other getUpdates request; make sure that only one bot instance is running
2025-03-21 16:40:59,857 (__init__.py:1243 MainThread) ERROR - TeleBot: "Exception traceback:
Traceback (most recent call last):
  File "/home/verner/content-assistant-bot/venv/lib/python3.10/site-packages/telebot/__init__.py", line 1234, in __threaded_polling
    polling_thread.raise_exceptions()
  File "/home/verner/content-assistant-bot/venv/lib/python3.10/site-packages/telebot/util.py", line 111, in raise_exceptions
    raise self.exception_info
  File "/home/verner/content-assistant-bot/venv/lib/python3.10/site-packages/telebot/util.py", line 93, in run
    task(*args, **kwargs)
  File "/home/verner/content-assistant-bot/venv/lib/python3.10/site-packages/telebot/__init__.py", line 688, in __retrieve_updates
    updates = self.get_updates(offset=(self.last_update_id + 1),
  File "/home/verner/content-assistant-bot/venv/lib/python3.10/site-packages/telebot/__init__.py", line 660, in get_updates
    json_updates = apihelper.get_updates(
  File "/home/verner/content-assistant-bot/venv/lib/python3.10/site-packages/telebot/apihelper.py", line 332, in get_updates
    return _make_request(token, method_url, params=payload)
  File "/home/verner/content-assistant-bot/venv/lib/python3.10/site-packages/telebot/apihelper.py", line 168, in _make_request
    json_result = _check_result(method_name, result)
  File "/home/verner/content-assistant-bot/venv/lib/python3.10/site-packages/telebot/apihelper.py", line 195, in _check_result
    raise ApiTelegramException(method_name, result, result_json)
telebot.apihelper.ApiTelegramException: A request to the Telegram API was unsuccessful. Error code: 409. Description: Conflict: terminated by other getUpdates request; make sure that only one bot instance is running
"
ERROR:TeleBot:Exception traceback:
Traceback (most recent call last):
  File "/home/verner/content-assistant-bot/venv/lib/python3.10/site-packages/telebot/__init__.py", line 1234, in __threaded_polling
    polling_thread.raise_exceptions()
  File "/home/verner/content-assistant-bot/venv/lib/python3.10/site-packages/telebot/util.py", line 111, in raise_exceptions
    raise self.exception_info
  File "/home/verner/content-assistant-bot/venv/lib/python3.10/site-packages/telebot/util.py", line 93, in run
    task(*args, **kwargs)
  File "/home/verner/content-assistant-bot/venv/lib/python3.10/site-packages/telebot/__init__.py", line 688, in __retrieve_updates
    updates = self.get_updates(offset=(self.last_update_id + 1),
  File "/home/verner/content-assistant-bot/venv/lib/python3.10/site-packages/telebot/__init__.py", line 660, in get_updates
    json_updates = apihelper.get_updates(
  File "/home/verner/content-assistant-bot/venv/lib/python3.10/site-packages/telebot/apihelper.py", line 332, in get_updates
    return _make_request(token, method_url, params=payload)
  File "/home/verner/content-assistant-bot/venv/lib/python3.10/site-packages/telebot/apihelper.py", line 168, in _make_request
    json_result = _check_result(method_name, result)
  File "/home/verner/content-assistant-bot/venv/lib/python3.10/site-packages/telebot/apihelper.py", line 195, in _check_result
    raise ApiTelegramException(method_name, result, result_json)
telebot.apihelper.ApiTelegramException: A request to the Telegram API was unsuccessful. Error code: 409. Description: Conflict: terminated by other getUpdates request; make sure that only one bot instance is running

2025-03-21 16:41:03,928 (__init__.py:1241 MainThread) ERROR - TeleBot: "Threaded polling exception: A request to the Telegram API was unsuccessful. Error code: 409. Description: Conflict: terminated by other getUpdates request; make sure that only one bot instance is running"
ERROR:TeleBot:Threaded polling exception: A request to the Telegram API was unsuccessful. Error code: 409. Description: Conflict: terminated by other getUpdates request; make sure that only one bot instance is running
2025-03-21 16:41:03,928 (__init__.py:1243 MainThread) ERROR - TeleBot: "Exception traceback:
Traceback (most recent call last):
  File "/home/verner/content-assistant-bot/venv/lib/python3.10/site-packages/telebot/__init__.py", line 1234, in __threaded_polling
    polling_thread.raise_exceptions()
  File "/home/verner/content-assistant-bot/venv/lib/python3.10/site-packages/telebot/util.py", line 111, in raise_exceptions
    raise self.exception_info
  File "/home/verner/content-assistant-bot/venv/lib/python3.10/site-packages/telebot/util.py", line 93, in run
    task(*args, **kwargs)
  File "/home/verner/content-assistant-bot/venv/lib/python3.10/site-packages/telebot/__init__.py", line 688, in __retrieve_updates
    updates = self.get_updates(offset=(self.last_update_id + 1),
  File "/home/verner/content-assistant-bot/venv/lib/python3.10/site-packages/telebot/__init__.py", line 660, in get_updates
    json_updates = apihelper.get_updates(
  File "/home/verner/content-assistant-bot/venv/lib/python3.10/site-packages/telebot/apihelper.py", line 332, in get_updates
    return _make_request(token, method_url, params=payload)
  File "/home/verner/content-assistant-bot/venv/lib/python3.10/site-packages/telebot/apihelper.py", line 168, in _make_request
    json_result = _check_result(method_name, result)
  File "/home/verner/content-assistant-bot/venv/lib/python3.10/site-packages/telebot/apihelper.py", line 195, in _check_result
    raise ApiTelegramException(method_name, result, result_json)
telebot.apihelper.ApiTelegramException: A request to the Telegram API was unsuccessful. Error code: 409. Description: Conflict: terminated by other getUpdates request; make sure that only one bot instance is running
"
ERROR:TeleBot:Exception traceback:
Traceback (most recent call last):
  File "/home/verner/content-assistant-bot/venv/lib/python3.10/site-packages/telebot/__init__.py", line 1234, in __threaded_polling
    polling_thread.raise_exceptions()
  File "/home/verner/content-assistant-bot/venv/lib/python3.10/site-packages/telebot/util.py", line 111, in raise_exceptions
    raise self.exception_info
  File "/home/verner/content-assistant-bot/venv/lib/python3.10/site-packages/telebot/util.py", line 93, in run
    task(*args, **kwargs)
  File "/home/verner/content-assistant-bot/venv/lib/python3.10/site-packages/telebot/__init__.py", line 688, in __retrieve_updates
    updates = self.get_updates(offset=(self.last_update_id + 1),
  File "/home/verner/content-assistant-bot/venv/lib/python3.10/site-packages/telebot/__init__.py", line 660, in get_updates
    json_updates = apihelper.get_updates(
  File "/home/verner/content-assistant-bot/venv/lib/python3.10/site-packages/telebot/apihelper.py", line 332, in get_updates
    return _make_request(token, method_url, params=payload)
  File "/home/verner/content-assistant-bot/venv/lib/python3.10/site-packages/telebot/apihelper.py", line 168, in _make_request
    json_result = _check_result(method_name, result)
  File "/home/verner/content-assistant-bot/venv/lib/python3.10/site-packages/telebot/apihelper.py", line 195, in _check_result
    raise ApiTelegramException(method_name, result, result_json)
telebot.apihelper.ApiTelegramException: A request to the Telegram API was unsuccessful. Error code: 409. Description: Conflict: terminated by other getUpdates request; make sure that only one bot instance is running

2025-03-21 16:41:09,082 (__init__.py:1241 MainThread) ERROR - TeleBot: "Threaded polling exception: A request to the Telegram API was unsuccessful. Error code: 409. Description: Conflict: terminated by other getUpdates request; make sure that only one bot instance is running"
ERROR:TeleBot:Threaded polling exception: A request to the Telegram API was unsuccessful. Error code: 409. Description: Conflict: terminated by other getUpdates request; make sure that only one bot instance is running
2025-03-21 16:41:09,082 (__init__.py:1243 MainThread) ERROR - TeleBot: "Exception traceback:
Traceback (most recent call last):
  File "/home/verner/content-assistant-bot/venv/lib/python3.10/site-packages/telebot/__init__.py", line 1234, in __threaded_polling
    polling_thread.raise_exceptions()
  File "/home/verner/content-assistant-bot/venv/lib/python3.10/site-packages/telebot/util.py", line 111, in raise_exceptions
    raise self.exception_info
  File "/home/verner/content-assistant-bot/venv/lib/python3.10/site-packages/telebot/util.py", line 93, in run
    task(*args, **kwargs)
  File "/home/verner/content-assistant-bot/venv/lib/python3.10/site-packages/telebot/__init__.py", line 688, in __retrieve_updates
    updates = self.get_updates(offset=(self.last_update_id + 1),
  File "/home/verner/content-assistant-bot/venv/lib/python3.10/site-packages/telebot/__init__.py", line 660, in get_updates
    json_updates = apihelper.get_updates(
  File "/home/verner/content-assistant-bot/venv/lib/python3.10/site-packages/telebot/apihelper.py", line 332, in get_updates
    return _make_request(token, method_url, params=payload)
  File "/home/verner/content-assistant-bot/venv/lib/python3.10/site-packages/telebot/apihelper.py", line 168, in _make_request
    json_result = _check_result(method_name, result)
  File "/home/verner/content-assistant-bot/venv/lib/python3.10/site-packages/telebot/apihelper.py", line 195, in _check_result
    raise ApiTelegramException(method_name, result, result_json)
telebot.apihelper.ApiTelegramException: A request to the Telegram API was unsuccessful. Error code: 409. Description: Conflict: terminated by other getUpdates request; make sure that only one bot instance is running
"
ERROR:TeleBot:Exception traceback:
Traceback (most recent call last):
  File "/home/verner/content-assistant-bot/venv/lib/python3.10/site-packages/telebot/__init__.py", line 1234, in __threaded_polling
    polling_thread.raise_exceptions()
  File "/home/verner/content-assistant-bot/venv/lib/python3.10/site-packages/telebot/util.py", line 111, in raise_exceptions
    raise self.exception_info
  File "/home/verner/content-assistant-bot/venv/lib/python3.10/site-packages/telebot/util.py", line 93, in run
    task(*args, **kwargs)
  File "/home/verner/content-assistant-bot/venv/lib/python3.10/site-packages/telebot/__init__.py", line 688, in __retrieve_updates
    updates = self.get_updates(offset=(self.last_update_id + 1),
  File "/home/verner/content-assistant-bot/venv/lib/python3.10/site-packages/telebot/__init__.py", line 660, in get_updates
    json_updates = apihelper.get_updates(
  File "/home/verner/content-assistant-bot/venv/lib/python3.10/site-packages/telebot/apihelper.py", line 332, in get_updates
    return _make_request(token, method_url, params=payload)
  File "/home/verner/content-assistant-bot/venv/lib/python3.10/site-packages/telebot/apihelper.py", line 168, in _make_request
    json_result = _check_result(method_name, result)
  File "/home/verner/content-assistant-bot/venv/lib/python3.10/site-packages/telebot/apihelper.py", line 195, in _check_result
    raise ApiTelegramException(method_name, result, result_json)
telebot.apihelper.ApiTelegramException: A request to the Telegram API was unsuccessful. Error code: 409. Description: Conflict: terminated by other getUpdates request; make sure that only one bot instance is running

2025-03-21 16:41:16,240 (__init__.py:1241 MainThread) ERROR - TeleBot: "Threaded polling exception: A request to the Telegram API was unsuccessful. Error code: 409. Description: Conflict: terminated by other getUpdates request; make sure that only one bot instance is running"
ERROR:TeleBot:Threaded polling exception: A request to the Telegram API was unsuccessful. Error code: 409. Description: Conflict: terminated by other getUpdates request; make sure that only one bot instance is running
2025-03-21 16:41:16,240 (__init__.py:1243 MainThread) ERROR - TeleBot: "Exception traceback:
Traceback (most recent call last):
  File "/home/verner/content-assistant-bot/venv/lib/python3.10/site-packages/telebot/__init__.py", line 1234, in __threaded_polling
    polling_thread.raise_exceptions()
  File "/home/verner/content-assistant-bot/venv/lib/python3.10/site-packages/telebot/util.py", line 111, in raise_exceptions
    raise self.exception_info
  File "/home/verner/content-assistant-bot/venv/lib/python3.10/site-packages/telebot/util.py", line 93, in run
    task(*args, **kwargs)
  File "/home/verner/content-assistant-bot/venv/lib/python3.10/site-packages/telebot/__init__.py", line 688, in __retrieve_updates
    updates = self.get_updates(offset=(self.last_update_id + 1),
  File "/home/verner/content-assistant-bot/venv/lib/python3.10/site-packages/telebot/__init__.py", line 660, in get_updates
    json_updates = apihelper.get_updates(
  File "/home/verner/content-assistant-bot/venv/lib/python3.10/site-packages/telebot/apihelper.py", line 332, in get_updates
    return _make_request(token, method_url, params=payload)
  File "/home/verner/content-assistant-bot/venv/lib/python3.10/site-packages/telebot/apihelper.py", line 168, in _make_request
    json_result = _check_result(method_name, result)
  File "/home/verner/content-assistant-bot/venv/lib/python3.10/site-packages/telebot/apihelper.py", line 195, in _check_result
    raise ApiTelegramException(method_name, result, result_json)
telebot.apihelper.ApiTelegramException: A request to the Telegram API was unsuccessful. Error code: 409. Description: Conflict: terminated by other getUpdates request; make sure that only one bot instance is running
"
ERROR:TeleBot:Exception traceback:
Traceback (most recent call last):
  File "/home/verner/content-assistant-bot/venv/lib/python3.10/site-packages/telebot/__init__.py", line 1234, in __threaded_polling
    polling_thread.raise_exceptions()
  File "/home/verner/content-assistant-bot/venv/lib/python3.10/site-packages/telebot/util.py", line 111, in raise_exceptions
    raise self.exception_info
  File "/home/verner/content-assistant-bot/venv/lib/python3.10/site-packages/telebot/util.py", line 93, in run
    task(*args, **kwargs)
  File "/home/verner/content-assistant-bot/venv/lib/python3.10/site-packages/telebot/__init__.py", line 688, in __retrieve_updates
    updates = self.get_updates(offset=(self.last_update_id + 1),
  File "/home/verner/content-assistant-bot/venv/lib/python3.10/site-packages/telebot/__init__.py", line 660, in get_updates
    json_updates = apihelper.get_updates(
  File "/home/verner/content-assistant-bot/venv/lib/python3.10/site-packages/telebot/apihelper.py", line 332, in get_updates
    return _make_request(token, method_url, params=payload)
  File "/home/verner/content-assistant-bot/venv/lib/python3.10/site-packages/telebot/apihelper.py", line 168, in _make_request
    json_result = _check_result(method_name, result)
  File "/home/verner/content-assistant-bot/venv/lib/python3.10/site-packages/telebot/apihelper.py", line 195, in _check_result
    raise ApiTelegramException(method_name, result, result_json)
telebot.apihelper.ApiTelegramException: A request to the Telegram API was unsuccessful. Error code: 409. Description: Conflict: terminated by other getUpdates request; make sure that only one bot instance is running

2025-03-21 16:41:24,320 (__init__.py:1241 MainThread) ERROR - TeleBot: "Threaded polling exception: A request to the Telegram API was unsuccessful. Error code: 409. Description: Conflict: terminated by other getUpdates request; make sure that only one bot instance is running"
ERROR:TeleBot:Threaded polling exception: A request to the Telegram API was unsuccessful. Error code: 409. Description: Conflict: terminated by other getUpdates request; make sure that only one bot instance is running
2025-03-21 16:41:24,320 (__init__.py:1243 MainThread) ERROR - TeleBot: "Exception traceback:
Traceback (most recent call last):
  File "/home/verner/content-assistant-bot/venv/lib/python3.10/site-packages/telebot/__init__.py", line 1234, in __threaded_polling
    polling_thread.raise_exceptions()
  File "/home/verner/content-assistant-bot/venv/lib/python3.10/site-packages/telebot/util.py", line 111, in raise_exceptions
    raise self.exception_info
  File "/home/verner/content-assistant-bot/venv/lib/python3.10/site-packages/telebot/util.py", line 93, in run
    task(*args, **kwargs)
  File "/home/verner/content-assistant-bot/venv/lib/python3.10/site-packages/telebot/__init__.py", line 688, in __retrieve_updates
    updates = self.get_updates(offset=(self.last_update_id + 1),
  File "/home/verner/content-assistant-bot/venv/lib/python3.10/site-packages/telebot/__init__.py", line 660, in get_updates
    json_updates = apihelper.get_updates(
  File "/home/verner/content-assistant-bot/venv/lib/python3.10/site-packages/telebot/apihelper.py", line 332, in get_updates
    return _make_request(token, method_url, params=payload)
  File "/home/verner/content-assistant-bot/venv/lib/python3.10/site-packages/telebot/apihelper.py", line 168, in _make_request
    json_result = _check_result(method_name, result)
  File "/home/verner/content-assistant-bot/venv/lib/python3.10/site-packages/telebot/apihelper.py", line 195, in _check_result
    raise ApiTelegramException(method_name, result, result_json)
telebot.apihelper.ApiTelegramException: A request to the Telegram API was unsuccessful. Error code: 409. Description: Conflict: terminated by other getUpdates request; make sure that only one bot instance is running
"
ERROR:TeleBot:Exception traceback:
Traceback (most recent call last):
  File "/home/verner/content-assistant-bot/venv/lib/python3.10/site-packages/telebot/__init__.py", line 1234, in __threaded_polling
    polling_thread.raise_exceptions()
  File "/home/verner/content-assistant-bot/venv/lib/python3.10/site-packages/telebot/util.py", line 111, in raise_exceptions
    raise self.exception_info
  File "/home/verner/content-assistant-bot/venv/lib/python3.10/site-packages/telebot/util.py", line 93, in run
    task(*args, **kwargs)
  File "/home/verner/content-assistant-bot/venv/lib/python3.10/site-packages/telebot/__init__.py", line 688, in __retrieve_updates
    updates = self.get_updates(offset=(self.last_update_id + 1),
  File "/home/verner/content-assistant-bot/venv/lib/python3.10/site-packages/telebot/__init__.py", line 660, in get_updates
    json_updates = apihelper.get_updates(
  File "/home/verner/content-assistant-bot/venv/lib/python3.10/site-packages/telebot/apihelper.py", line 332, in get_updates
    return _make_request(token, method_url, params=payload)
  File "/home/verner/content-assistant-bot/venv/lib/python3.10/site-packages/telebot/apihelper.py", line 168, in _make_request
    json_result = _check_result(method_name, result)
  File "/home/verner/content-assistant-bot/venv/lib/python3.10/site-packages/telebot/apihelper.py", line 195, in _check_result
    raise ApiTelegramException(method_name, result, result_json)
telebot.apihelper.ApiTelegramException: A request to the Telegram API was unsuccessful. Error code: 409. Description: Conflict: terminated by other getUpdates request; make sure that only one bot instance is running

2025-03-21 16:41:40,612 (__init__.py:1241 MainThread) ERROR - TeleBot: "Threaded polling exception: A request to the Telegram API was unsuccessful. Error code: 409. Description: Conflict: terminated by other getUpdates request; make sure that only one bot instance is running"
ERROR:TeleBot:Threaded polling exception: A request to the Telegram API was unsuccessful. Error code: 409. Description: Conflict: terminated by other getUpdates request; make sure that only one bot instance is running
2025-03-21 16:41:40,613 (__init__.py:1243 MainThread) ERROR - TeleBot: "Exception traceback:
Traceback (most recent call last):
  File "/home/verner/content-assistant-bot/venv/lib/python3.10/site-packages/telebot/__init__.py", line 1234, in __threaded_polling
    polling_thread.raise_exceptions()
  File "/home/verner/content-assistant-bot/venv/lib/python3.10/site-packages/telebot/util.py", line 111, in raise_exceptions
    raise self.exception_info
  File "/home/verner/content-assistant-bot/venv/lib/python3.10/site-packages/telebot/util.py", line 93, in run
    task(*args, **kwargs)
  File "/home/verner/content-assistant-bot/venv/lib/python3.10/site-packages/telebot/__init__.py", line 688, in __retrieve_updates
    updates = self.get_updates(offset=(self.last_update_id + 1),
  File "/home/verner/content-assistant-bot/venv/lib/python3.10/site-packages/telebot/__init__.py", line 660, in get_updates
    json_updates = apihelper.get_updates(
  File "/home/verner/content-assistant-bot/venv/lib/python3.10/site-packages/telebot/apihelper.py", line 332, in get_updates
    return _make_request(token, method_url, params=payload)
  File "/home/verner/content-assistant-bot/venv/lib/python3.10/site-packages/telebot/apihelper.py", line 168, in _make_request
    json_result = _check_result(method_name, result)
  File "/home/verner/content-assistant-bot/venv/lib/python3.10/site-packages/telebot/apihelper.py", line 195, in _check_result
    raise ApiTelegramException(method_name, result, result_json)
telebot.apihelper.ApiTelegramException: A request to the Telegram API was unsuccessful. Error code: 409. Description: Conflict: terminated by other getUpdates request; make sure that only one bot instance is running
"
ERROR:TeleBot:Exception traceback:
Traceback (most recent call last):
  File "/home/verner/content-assistant-bot/venv/lib/python3.10/site-packages/telebot/__init__.py", line 1234, in __threaded_polling
    polling_thread.raise_exceptions()
  File "/home/verner/content-assistant-bot/venv/lib/python3.10/site-packages/telebot/util.py", line 111, in raise_exceptions
    raise self.exception_info
  File "/home/verner/content-assistant-bot/venv/lib/python3.10/site-packages/telebot/util.py", line 93, in run
    task(*args, **kwargs)
  File "/home/verner/content-assistant-bot/venv/lib/python3.10/site-packages/telebot/__init__.py", line 688, in __retrieve_updates
    updates = self.get_updates(offset=(self.last_update_id + 1),
  File "/home/verner/content-assistant-bot/venv/lib/python3.10/site-packages/telebot/__init__.py", line 660, in get_updates
    json_updates = apihelper.get_updates(
  File "/home/verner/content-assistant-bot/venv/lib/python3.10/site-packages/telebot/apihelper.py", line 332, in get_updates
    return _make_request(token, method_url, params=payload)
  File "/home/verner/content-assistant-bot/venv/lib/python3.10/site-packages/telebot/apihelper.py", line 168, in _make_request
    json_result = _check_result(method_name, result)
  File "/home/verner/content-assistant-bot/venv/lib/python3.10/site-packages/telebot/apihelper.py", line 195, in _check_result
    raise ApiTelegramException(method_name, result, result_json)
telebot.apihelper.ApiTelegramException: A request to the Telegram API was unsuccessful. Error code: 409. Description: Conflict: terminated by other getUpdates request; make sure that only one bot instance is running

